<mujoco model="serialleg_closed_chain_v2_spring">
  <compiler angle="radian" meshdir="../meshes" autolimits="true" strippath="false" />
  <option timestep="0.002" solver="Newton" cone="pyramidal" />
  <visual>
    <global offwidth="1280" offheight="720" />
  </visual>
  <default>
    <geom solref="0.004 1.5" solimp="0.85 0.99 0.005" />
    <joint damping="0" />
  </default>
  <asset>
    <texture name="grid" type="2d" builtin="checker" width="512" height="512" rgb1=".1 .2 .3" rgb2=".2 .3 .4" />
    <material name="grid" texture="grid" texrepeat="1 1" texuniform="true" reflectance=".2" />
    <mesh name="visual_lf_thigh" file="lf_thigh_link.STL" />
    <mesh name="visual_lf_calf_1" file="lf_calf_1_link.STL" />
    <mesh name="visual_lf_calf_2" file="lf_calf_2_link.STL" />
    <mesh name="visual_lf_calf_3" file="lf_calf_3_link.STL" />
    <mesh name="visual_lf_wheel" file="lf_wheel_link.STL" />
    <mesh name="visual_rf_thigh" file="rf_thigh_link.STL" />
    <mesh name="visual_rf_calf_1" file="rf_calf_1_link.STL" />
    <mesh name="visual_rf_calf_2" file="rf_calf_2_link.STL" />
    <mesh name="visual_rf_calf_3" file="rf_calf_3_link.STL" />
    <mesh name="visual_rf_wheel" file="rf_wheel_link.STL" />
    <mesh name="swcol_base_link_00" file="sw_collision/base_link/base_link_sw_env_00.stl" />
    <mesh name="swcol_base_link_01" file="sw_collision/base_link/base_link_sw_env_01.stl" />
    <mesh name="swcol_base_link_02" file="sw_collision/base_link/base_link_sw_env_02.stl" />
    <mesh name="swcol_base_link_03" file="sw_collision/base_link/base_link_sw_env_03.stl" />
    <mesh name="swcol_base_link_04" file="sw_collision/base_link/base_link_sw_env_04.stl" />
    <mesh name="swcol_base_link_05" file="sw_collision/base_link/base_link_sw_env_05.stl" />
    <mesh name="swcol_base_link_06" file="sw_collision/base_link/base_link_sw_env_06.stl" />
    <mesh name="swcol_base_link_07" file="sw_collision/base_link/base_link_sw_env_07.stl" />
    <mesh name="swcol_base_link_08" file="sw_collision/base_link/base_link_sw_env_08.stl" />
    <mesh name="swcol_base_link_09" file="sw_collision/base_link/base_link_sw_env_09.stl" />
    <mesh name="swcol_base_link_10" file="sw_collision/base_link/base_link_sw_env_10.stl" />
    <mesh name="swcol_base_link_11" file="sw_collision/base_link/base_link_sw_env_11.stl" />
    <mesh name="swcol_base_link_12" file="sw_collision/base_link/base_link_sw_env_12.stl" />
    <mesh name="swcol_base_link_13" file="sw_collision/base_link/base_link_sw_env_13.stl" />
    <mesh name="swcol_base_link_14" file="sw_collision/base_link/base_link_sw_env_14.stl" />
    <mesh name="swcol_base_link_15" file="sw_collision/base_link/base_link_sw_env_15.stl" />
    <mesh name="swcol_base_link_16" file="sw_collision/base_link/base_link_sw_env_16.stl" />
    <mesh name="swcol_base_link_17" file="sw_collision/base_link/base_link_sw_env_17.stl" />
    <mesh name="swcol_base_link_18" file="sw_collision/base_link/base_link_sw_env_18.stl" />
    <mesh name="swcol_base_link_19" file="sw_collision/base_link/base_link_sw_env_19.stl" />
    <mesh name="swcol_base_link_20" file="sw_collision/base_link/base_link_sw_env_20.stl" />
    <mesh name="swcol_base_link_21" file="sw_collision/base_link/base_link_sw_env_21.stl" />
    <mesh name="swcol_base_link_22" file="sw_collision/base_link/base_link_sw_env_22.stl" />
    <mesh name="swcol_base_link_23" file="sw_collision/base_link/base_link_sw_env_23.stl" />
    <mesh name="swcol_base_link_24" file="sw_collision/base_link/base_link_sw_env_24.stl" />
    <mesh name="swcol_base_link_25" file="sw_collision/base_link/base_link_sw_env_25.stl" />
    <mesh name="swcol_base_link_26" file="sw_collision/base_link/base_link_sw_env_26.stl" />
    <mesh name="swcol_base_link_27" file="sw_collision/base_link/base_link_sw_env_27.stl" />
    <mesh name="swcol_base_link_28" file="sw_collision/base_link/base_link_sw_env_28.stl" />
    <mesh name="swcol_base_link_29" file="sw_collision/base_link/base_link_sw_env_29.stl" />
    <mesh name="swcol_base_link_30" file="sw_collision/base_link/base_link_sw_env_30.stl" />
    <mesh name="swcol_base_link_31" file="sw_collision/base_link/base_link_sw_env_31.stl" />
    <mesh name="swcol_base_link_32" file="sw_collision/base_link/base_link_sw_env_32.stl" />
    <mesh name="swcol_base_link_33" file="sw_collision/base_link/base_link_sw_env_33.stl" />
    <mesh name="swcol_base_link_34" file="sw_collision/base_link/base_link_sw_env_34.stl" />
    <mesh name="swcol_base_link_35" file="sw_collision/base_link/base_link_sw_env_35.stl" />
    <mesh name="swcol_base_link_36" file="sw_collision/base_link/base_link_sw_env_36.stl" />
    <mesh name="swcol_base_link_37" file="sw_collision/base_link/base_link_sw_env_37.stl" />
    <mesh name="swcol_base_link_38" file="sw_collision/base_link/base_link_sw_env_38.stl" />
    <mesh name="swcol_base_link_39" file="sw_collision/base_link/base_link_sw_env_39.stl" />
    <mesh name="swcol_base_link_40" file="sw_collision/base_link/base_link_sw_env_40.stl" />
    <mesh name="swcol_base_link_41" file="sw_collision/base_link/base_link_sw_env_41.stl" />
    <mesh name="swcol_base_link_42" file="sw_collision/base_link/base_link_sw_env_42.stl" />
    <mesh name="swcol_base_link_43" file="sw_collision/base_link/base_link_sw_env_43.stl" />
    <mesh name="swcol_base_link_44" file="sw_collision/base_link/base_link_sw_env_44.stl" />
    <mesh name="swcol_base_link_45" file="sw_collision/base_link/base_link_sw_env_45.stl" />
    <mesh name="swcol_base_link_46" file="sw_collision/base_link/base_link_sw_env_46.stl" />
    <mesh name="swcol_base_link_47" file="sw_collision/base_link/base_link_sw_env_47.stl" />
    <mesh name="swcol_lf0_Link_00" file="sw_collision/lf0_Link/lf0_Link_sw_env_00.stl" />
    <mesh name="swcol_lf0_Link_01" file="sw_collision/lf0_Link/lf0_Link_sw_env_01.stl" />
    <mesh name="swcol_rf0_Link_00" file="sw_collision/rf0_Link/rf0_Link_sw_env_00.stl" />
    <mesh name="swcol_rf0_Link_01" file="sw_collision/rf0_Link/rf0_Link_sw_env_01.stl" />
    <mesh name="swcol_lf1_Link_00" file="sw_collision/lf1_Link/lf1_Link_sw_env_00.stl" />
    <mesh name="swcol_rf1_Link_00" file="sw_collision/rf1_Link/rf1_Link_sw_env_00.stl" />
    <mesh name="swcol_l_wheel_Link_00" file="sw_collision/l_wheel_Link/l_wheel_Link_sw_env_00.stl" />
    <mesh name="swcol_l_wheel_Link_01" file="sw_collision/l_wheel_Link/l_wheel_Link_sw_env_01.stl" />
    <mesh name="swcol_r_wheel_Link_00" file="sw_collision/r_wheel_Link/r_wheel_Link_sw_env_00.stl" />
    <mesh name="swcol_r_wheel_Link_01" file="sw_collision/r_wheel_Link/r_wheel_Link_sw_env_01.stl" />
    <mesh name="swcol_l_drive_bar_Link_00" file="sw_collision/l_drive_bar_Link/l_drive_bar_Link_sw_env_00.stl" />
    <mesh name="swcol_r_drive_bar_Link_00" file="sw_collision/r_drive_bar_Link/r_drive_bar_Link_sw_env_00.stl" />
    <mesh name="swcol_l_coupler_Link_00" file="sw_collision/l_coupler_Link/l_coupler_Link_sw_env_00.stl" />
    <mesh name="swcol_r_coupler_Link_00" file="sw_collision/r_coupler_Link/r_coupler_Link_sw_env_00.stl" />
  </asset>
  <worldbody>
    <geom name="floor" type="plane" size="0 0 .05" material="grid" friction="0.8 0.005 0.0001" contype="2" conaffinity="1" />
    <light name="spotlight" mode="targetbodycom" target="base_link" diffuse=".8 .8 .8" specular="0.3 0.3 0.3" pos="0 -6 4" cutoff="30" />
    <body name="base_link" pos="0 0 0.30">
      <freejoint />
      <inertial pos="-0.01767637 0.01380473 -0.03322290" mass="10.79176890" diaginertia="0.14492885 0.21274637 0.31107460" quat="0.99953166 0.00493832 0.02409342 0.01820912" />
      <geom name="base_link_sw_env_col_00" type="mesh" group="0" contype="1" conaffinity="2" mesh="swcol_base_link_00" />
      <geom name="base_link_sw_env_col_01" type="mesh" group="0" contype="1" conaffinity="2" mesh="swcol_base_link_01" />
      <geom name="base_link_sw_env_col_02" type="mesh" group="0" contype="1" conaffinity="2" mesh="swcol_base_link_02" />
      <geom name="base_link_sw_env_col_03" type="mesh" group="0" contype="1" conaffinity="2" mesh="swcol_base_link_03" />
      <geom name="base_link_sw_env_col_04" type="mesh" group="0" contype="1" conaffinity="2" mesh="swcol_base_link_04" />
      <geom name="base_link_sw_env_col_05" type="mesh" group="0" contype="1" conaffinity="2" mesh="swcol_base_link_05" />
      <geom name="base_link_sw_env_col_06" type="mesh" group="0" contype="1" conaffinity="2" mesh="swcol_base_link_06" />
      <geom name="base_link_sw_env_col_07" type="mesh" group="0" contype="1" conaffinity="2" mesh="swcol_base_link_07" />
      <geom name="base_link_sw_env_col_08" type="mesh" group="0" contype="1" conaffinity="2" mesh="swcol_base_link_08" />
      <geom name="base_link_sw_env_col_09" type="mesh" group="0" contype="1" conaffinity="2" mesh="swcol_base_link_09" />
      <geom name="base_link_sw_env_col_10" type="mesh" group="0" contype="1" conaffinity="2" mesh="swcol_base_link_10" />
      <geom name="base_link_sw_env_col_11" type="mesh" group="0" contype="1" conaffinity="2" mesh="swcol_base_link_11" />
      <geom name="base_link_sw_env_col_12" type="mesh" group="0" contype="1" conaffinity="2" mesh="swcol_base_link_12" />
      <geom name="base_link_sw_env_col_13" type="mesh" group="0" contype="1" conaffinity="2" mesh="swcol_base_link_13" />
      <geom name="base_link_sw_env_col_14" type="mesh" group="0" contype="1" conaffinity="2" mesh="swcol_base_link_14" />
      <geom name="base_link_sw_env_col_15" type="mesh" group="0" contype="1" conaffinity="2" mesh="swcol_base_link_15" />
      <geom name="base_link_sw_env_col_16" type="mesh" group="0" contype="1" conaffinity="2" mesh="swcol_base_link_16" />
      <geom name="base_link_sw_env_col_17" type="mesh" group="0" contype="1" conaffinity="2" mesh="swcol_base_link_17" />
      <geom name="base_link_sw_env_col_18" type="mesh" group="0" contype="1" conaffinity="2" mesh="swcol_base_link_18" />
      <geom name="base_link_sw_env_col_19" type="mesh" group="0" contype="1" conaffinity="2" mesh="swcol_base_link_19" />
      <geom name="base_link_sw_env_col_20" type="mesh" group="0" contype="1" conaffinity="2" mesh="swcol_base_link_20" />
      <geom name="base_link_sw_env_col_21" type="mesh" group="0" contype="1" conaffinity="2" mesh="swcol_base_link_21" />
      <geom name="base_link_sw_env_col_22" type="mesh" group="0" contype="1" conaffinity="2" mesh="swcol_base_link_22" />
      <geom name="base_link_sw_env_col_23" type="mesh" group="0" contype="1" conaffinity="2" mesh="swcol_base_link_23" />
      <geom name="base_link_sw_env_col_24" type="mesh" group="0" contype="1" conaffinity="2" mesh="swcol_base_link_24" />
      <geom name="base_link_sw_env_col_25" type="mesh" group="0" contype="1" conaffinity="2" mesh="swcol_base_link_25" />
      <geom name="base_link_sw_env_col_26" type="mesh" group="0" contype="1" conaffinity="2" mesh="swcol_base_link_26" />
      <geom name="base_link_sw_env_col_27" type="mesh" group="0" contype="1" conaffinity="2" mesh="swcol_base_link_27" />
      <geom name="base_link_sw_env_col_28" type="mesh" group="0" contype="1" conaffinity="2" mesh="swcol_base_link_28" />
      <geom name="base_link_sw_env_col_29" type="mesh" group="0" contype="1" conaffinity="2" mesh="swcol_base_link_29" />
      <geom name="base_link_sw_env_col_30" type="mesh" group="0" contype="1" conaffinity="2" mesh="swcol_base_link_30" />
      <geom name="base_link_sw_env_col_31" type="mesh" group="0" contype="1" conaffinity="2" mesh="swcol_base_link_31" />
      <geom name="base_link_sw_env_col_32" type="mesh" group="0" contype="1" conaffinity="2" mesh="swcol_base_link_32" />
      <geom name="base_link_sw_env_col_33" type="mesh" group="0" contype="1" conaffinity="2" mesh="swcol_base_link_33" />
      <geom name="base_link_sw_env_col_34" type="mesh" group="0" contype="1" conaffinity="2" mesh="swcol_base_link_34" />
      <geom name="base_link_sw_env_col_35" type="mesh" group="0" contype="1" conaffinity="2" mesh="swcol_base_link_35" />
      <geom name="base_link_sw_env_col_36" type="mesh" group="0" contype="1" conaffinity="2" mesh="swcol_base_link_36" />
      <geom name="base_link_sw_env_col_37" type="mesh" group="0" contype="1" conaffinity="2" mesh="swcol_base_link_37" />
      <geom name="base_link_sw_env_col_38" type="mesh" group="0" contype="1" conaffinity="2" mesh="swcol_base_link_38" />
      <geom name="base_link_sw_env_col_39" type="mesh" group="0" contype="1" conaffinity="2" mesh="swcol_base_link_39" />
      <geom name="base_link_sw_env_col_40" type="mesh" group="0" contype="1" conaffinity="2" mesh="swcol_base_link_40" />
      <geom name="base_link_sw_env_col_41" type="mesh" group="0" contype="1" conaffinity="2" mesh="swcol_base_link_41" />
      <geom name="base_link_sw_env_col_42" type="mesh" group="0" contype="1" conaffinity="2" mesh="swcol_base_link_42" />
      <geom name="base_link_sw_env_col_43" type="mesh" group="0" contype="1" conaffinity="2" mesh="swcol_base_link_43" />
      <geom name="base_link_sw_env_col_44" type="mesh" group="0" contype="1" conaffinity="2" mesh="swcol_base_link_44" />
      <geom name="base_link_sw_env_col_45" type="mesh" group="0" contype="1" conaffinity="2" mesh="swcol_base_link_45" />
      <geom name="base_link_sw_env_col_46" type="mesh" group="0" contype="1" conaffinity="2" mesh="swcol_base_link_46" />
      <geom name="base_link_sw_env_col_47" type="mesh" group="0" contype="1" conaffinity="2" mesh="swcol_base_link_47" />
      <body name="lf0_Link" pos="0 0.16885 0">
        <joint name="lf0_Joint" type="hinge" axis="0 1 0" />
        <inertial pos="-0.08566293 0.00525819 0.00414942" mass="0.36877339" diaginertia="0.00016423 0.00222749 0.00232930" quat="0.72749268 0.68601336 0.00031414 -0.01183070" />
        <geom type="mesh" mesh="visual_lf_thigh" pos="0 0 0" name="lf0_Link_visual" contype="0" conaffinity="0" group="1" />
        <site name="lf_thigh_end" pos="-0.17993 0.009275 0.0049" size="0.008" rgba="1 0 0 1" />
        <geom name="lf0_Link_sw_env_col_00" type="mesh" group="0" contype="1" conaffinity="2" mesh="swcol_lf0_Link_00" />
        <geom name="lf0_Link_sw_env_col_01" type="mesh" group="0" contype="1" conaffinity="2" mesh="swcol_lf0_Link_01" />
      </body>
      <body name="l_drive_bar_Link" pos="0 0.16885 0">
        <joint name="l_drive_bar_Joint" type="hinge" axis="0 1 0" />
        <inertial pos="0.01185501 0.01367042 0.01339557" mass="0.04635322" diaginertia="0.00000884 0.00003261 0.00004090" quat="-0.29095745 -0.28978302 -0.64432268 0.64514948" />
        <geom type="mesh" mesh="visual_lf_calf_1" pos="0 0 0" name="l_drive_bar_Link_visual" contype="0" conaffinity="0" group="1" />
        <site name="l_spring_p1" pos="0.02004768 0.00345000 0.02265288" group="4" />
        <geom name="l_drive_bar_Link_sw_env_col_00" type="mesh" group="0" contype="1" conaffinity="2" mesh="swcol_l_drive_bar_Link_00" />
        <body name="l_coupler_Link" pos="0.04009536 0.00690000 0.04530576">
          <joint name="l_coupler_Joint" type="hinge" axis="0 1 0" />
          <inertial pos="-0.04651689 0.00499986 -0.01682037" mass="0.06957214" diaginertia="0.00004910 0.00014237 0.00019029" quat="0.71775567 -0.68120211 0.09128656 0.11161205" />
          <geom type="mesh" mesh="visual_lf_calf_2" pos="0 0 0" name="l_coupler_Link_visual" contype="0" conaffinity="0" group="1" />
          <geom name="l_coupler_Link_sw_env_col_00" type="mesh" group="0" contype="1" conaffinity="2" mesh="swcol_l_coupler_Link_00" />
          <body name="lf1_Link" pos="-0.17 0.0146 0.0010863">
            <joint name="lf1_Joint" type="hinge" axis="0 -1 0" />
            <inertial pos="-0.06239656 -0.00180861 -0.09785042" mass="0.36819368" diaginertia="0.00055542 0.00380412 0.00433340" quat="0.67385492 -0.68271060 -0.19101628 -0.20817917" />
            <geom type="mesh" mesh="visual_lf_calf_3" pos="0 0 0" name="lf1_Link_visual" contype="0" conaffinity="0" group="1" />
            <site name="lf_calf_closure" pos="-0.05002536 -0.012225 -0.04149206" size="0.008" rgba="0 1 0 1" />
            <site name="l_spring_p2" pos="-0.02501268 -0.00611250 -0.02074603" group="4" />
            <geom name="lf1_Link_sw_env_col_00" type="mesh" group="0" contype="1" conaffinity="2" mesh="swcol_lf1_Link_00" />
            <body name="l_wheel_Link" pos="-0.15699 0.02705 -0.21049">
              <joint name="l_wheel_Joint" type="hinge" axis="0 1 0" />
              <inertial pos="0.04265601 -0.01064545 0.02530011" mass="0.32418749" diaginertia="0.00027797 0.00512705 0.00535190" quat="0.68744799 -0.67498843 -0.16102142 -0.21419146" />
              <geom type="mesh" mesh="visual_lf_wheel" pos="0 0 0" name="l_wheel_Link_visual" contype="0" conaffinity="0" group="1" />
              <geom name="l_wheel_Link_sw_env_col_00" type="mesh" group="0" contype="1" conaffinity="2" mesh="swcol_l_wheel_Link_00" />
              <geom name="l_wheel_Link_sw_env_col_01" type="mesh" group="0" contype="1" conaffinity="2" mesh="swcol_l_wheel_Link_01" />
            </body>
          </body>
        </body>
      </body>
      <body name="rf0_Link" pos="0 -0.16885 0">
        <joint name="rf0_Joint" type="hinge" axis="0 -1 0" />
        <inertial pos="-0.08566293 -0.00525819 0.00414942" mass="0.36877339" diaginertia="0.00016423 0.00222749 0.00232930" quat="0.72749268 -0.68601336 0.00031414 0.01183070" />
        <geom type="mesh" mesh="visual_rf_thigh" pos="0 0 0" name="rf0_Link_visual" contype="0" conaffinity="0" group="1" />
        <site name="rf_thigh_end" pos="-0.17993 -0.009275 0.0049" size="0.008" rgba="1 0 0 1" />
        <geom name="rf0_Link_sw_env_col_00" type="mesh" group="0" contype="1" conaffinity="2" mesh="swcol_rf0_Link_00" />
        <geom name="rf0_Link_sw_env_col_01" type="mesh" group="0" contype="1" conaffinity="2" mesh="swcol_rf0_Link_01" />
      </body>
      <body name="r_drive_bar_Link" pos="0 -0.16885 0">
        <joint name="r_drive_bar_Joint" type="hinge" axis="0 -1 0" />
        <inertial pos="0.01185501 -0.01367042 0.01339557" mass="0.04635322" diaginertia="0.00000884 0.00003261 0.00004090" quat="0.64514948 -0.64432268 -0.28978302 -0.29095745" />
        <geom type="mesh" mesh="visual_rf_calf_1" pos="0 0 0" name="r_drive_bar_Link_visual" contype="0" conaffinity="0" group="1" />
        <site name="r_spring_p1" pos="0.02004750 -0.00345000 0.02265300" group="4" />
        <geom name="r_drive_bar_Link_sw_env_col_00" type="mesh" group="0" contype="1" conaffinity="2" mesh="swcol_r_drive_bar_Link_00" />
        <body name="r_coupler_Link" pos="0.040095 -0.0069 0.045306">
          <joint name="r_coupler_Joint" type="hinge" axis="0 -1 0" />
          <inertial pos="-0.04651653 -0.00499986 -0.01682061" mass="0.06957214" diaginertia="0.00004910 0.00014237 0.00019029" quat="0.71775567 0.68120211 0.09128656 -0.11161205" />
          <geom type="mesh" mesh="visual_rf_calf_2" pos="0 0 0" name="r_coupler_Link_visual" contype="0" conaffinity="0" group="1" />
          <geom name="r_coupler_Link_sw_env_col_00" type="mesh" group="0" contype="1" conaffinity="2" mesh="swcol_r_coupler_Link_00" />
          <body name="rf1_Link" pos="-0.17 -0.0131 0.0010863">
            <joint name="rf1_Joint" type="hinge" axis="0 1 0" />
            <inertial pos="-0.06239620 0.00030861 -0.09785066" mass="0.36819368" diaginertia="0.00055542 0.00380412 0.00433340" quat="0.67385492 0.68271060 -0.19101628 0.20817917" />
            <geom type="mesh" mesh="visual_rf_calf_3" pos="0 0 0" name="rf1_Link_visual" contype="0" conaffinity="0" group="1" />
            <site name="rf_calf_closure" pos="-0.050025 0.010725 -0.0414923" size="0.008" rgba="0 1 0 1" />
            <site name="r_spring_p2" pos="-0.02501250 0.00536250 -0.02074615" group="4" />
            <geom name="rf1_Link_sw_env_col_00" type="mesh" group="0" contype="1" conaffinity="2" mesh="swcol_rf1_Link_00" />
            <body name="r_wheel_Link" pos="-0.15699 -0.02705 -0.21049">
              <joint name="r_wheel_Joint" type="hinge" axis="0 -1 0" />
              <inertial pos="0.04265637 0.00914545 0.02529987" mass="0.32418749" diaginertia="0.00027797 0.00512705 0.00535190" quat="0.68744799 0.67498843 -0.16102142 0.21419146" />
              <geom type="mesh" mesh="visual_rf_wheel" pos="0 0 0" name="r_wheel_Link_visual" contype="0" conaffinity="0" group="1" />
              <geom name="r_wheel_Link_sw_env_col_00" type="mesh" group="0" contype="1" conaffinity="2" mesh="swcol_r_wheel_Link_00" />
              <geom name="r_wheel_Link_sw_env_col_01" type="mesh" group="0" contype="1" conaffinity="2" mesh="swcol_r_wheel_Link_01" />
            </body>
          </body>
        </body>
      </body>
    </body>
  </worldbody>
  <equality>
    <connect body1="lf0_Link" body2="lf1_Link" anchor="-0.17993 0.009275 0.0049" solref="0.002 1" solimp="0.95 0.99 0.001" />
    <connect body1="rf0_Link" body2="rf1_Link" anchor="-0.17993 -0.009275 0.0049" solref="0.002 1" solimp="0.95 0.99 0.001" />
  </equality>
  <tendon>
    <fixed name="l_active_rod_angle" limited="true" range="0.655 2.268" solreflimit="0.001 1" solimplimit="0.99 0.999 0.00001 0.5 2">
      <joint joint="lf0_Joint" coef="1" />
      <joint joint="l_drive_bar_Joint" coef="-1" />
    </fixed>
    <fixed name="r_active_rod_angle" limited="true" range="0.655 2.268" solreflimit="0.001 1" solimplimit="0.99 0.999 0.00001 0.5 2">
      <joint joint="r_drive_bar_Joint" coef="1" />
      <joint joint="rf0_Joint" coef="-1" />
    </fixed>
    <spatial name="l_knee_spring" width="0.003" rgba="0.2 0.6 1 1">
      <site site="l_spring_p1" />
      <site site="l_spring_p2" />
    </spatial>
    <spatial name="r_knee_spring" width="0.003" rgba="0.2 0.6 1 1">
      <site site="r_spring_p1" />
      <site site="r_spring_p2" />
    </spatial>
  </tendon>
  <actuator>
    <general name="l_knee_gas_spring" tendon="l_knee_spring" dyntype="none" gaintype="fixed" biastype="affine" gainprm="0" biasprm="300 0 0" />
    <general name="r_knee_gas_spring" tendon="r_knee_spring" dyntype="none" gaintype="fixed" biastype="affine" gainprm="0" biasprm="300 0 0" />
  </actuator>
</mujoco>
