<mujoco model="serialleg_fidelity_cylinder_wheels_closedchain_spring">
  <compiler angle="radian" meshdir="../meshes" autolimits="true" strippath="false" />
  <size njmax="512" nconmax="128" />
  <option timestep="0.005" iterations="200" solver="Newton" cone="pyramidal" noslip_iterations="10" />
  <!-- 闭链和气弹簧模型：保留四连杆被动机构、闭链约束和膝部空间 tendon。 -->
  <default>
    <geom solref="0.004 1.5" solimp="0.85 0.99 0.005" />
  </default>
  <asset>
    <texture name="grid" type="2d" builtin="checker" width="512" height="512" rgb1=".1 .2 .3" rgb2=".2 .3 .4" />
    <material name="grid" texture="grid" texrepeat="1 1" texuniform="true" reflectance=".2" />
    <mesh name="generated_base_link_part000" file="_mjc_generated_collision/base_link_part000.stl" />
    <mesh name="generated_base_link_part001" file="_mjc_generated_collision/base_link_part001.stl" />
    <mesh name="generated_base_link_part002" file="_mjc_generated_collision/base_link_part002.stl" />
    <mesh name="generated_base_link_part003" file="_mjc_generated_collision/base_link_part003.stl" />
    <mesh name="generated_base_link_part004" file="_mjc_generated_collision/base_link_part004.stl" />
    <mesh name="generated_base_link_part005" file="_mjc_generated_collision/base_link_part005.stl" />
    <mesh name="generated_base_link_part006" file="_mjc_generated_collision/base_link_part006.stl" />
    <mesh name="generated_base_link_part007" file="_mjc_generated_collision/base_link_part007.stl" />
    <mesh name="generated_base_link_part008" file="_mjc_generated_collision/base_link_part008.stl" />
    <mesh name="generated_base_link_part009" file="_mjc_generated_collision/base_link_part009.stl" />
    <mesh name="generated_base_link_part010" file="_mjc_generated_collision/base_link_part010.stl" />
    <mesh name="visual_Left_calf_link" file="Left_calf_link.STL" />
    <mesh name="visual_Left_thigh_link" file="Left_thigh_link.STL" />
    <mesh name="visual_Left_wheel_link" file="Left_wheel_link.STL" />
    <mesh name="visual_Right_calf_link" file="Right_calf_link.STL" />
    <mesh name="visual_Right_thigh_link" file="Right_thigh_link.STL" />
    <mesh name="visual_Right_wheel_link" file="Right_wheel_link.STL" />
  </asset>
  <worldbody>
    <geom name="floor" type="plane" size="0 0 .05" material="grid" friction="0.8 0.005 0.0001" contype="2" conaffinity="1" />
    <light name="spotlight" mode="targetbodycom" target="base_link" diffuse=".8 .8 .8" specular="0.3 0.3 0.3" pos="0 -6 4" cutoff="30" />
    <body name="base_link" pos="0 0 0.301">
      <freejoint />
      <inertial pos="-0.01780372 0.01307697 -0.03342401" mass="10.7454126" diaginertia="0.143489521 0.212552576 0.309691433" quat="0.999565642 0.00301777024 0.0243203337 0.0163689112" />
      <geom type="mesh" mesh="generated_base_link_part000" pos="0 0 0" name="base_link_collision_0" contype="1" conaffinity="2" group="0" />
      <geom type="mesh" mesh="generated_base_link_part001" pos="0 0 0" name="base_link_collision_1" contype="1" conaffinity="2" group="0" />
      <geom type="mesh" mesh="generated_base_link_part002" pos="0 0 0" name="base_link_collision_2" contype="1" conaffinity="2" group="0" />
      <geom type="mesh" mesh="generated_base_link_part003" pos="0 0 0" name="base_link_collision_3" contype="1" conaffinity="2" group="0" />
      <geom type="mesh" mesh="generated_base_link_part004" pos="0 0 0" name="base_link_collision_4" contype="1" conaffinity="2" group="0" />
      <geom type="mesh" mesh="generated_base_link_part005" pos="0 0 0" name="base_link_collision_5" contype="1" conaffinity="2" group="0" />
      <geom type="mesh" mesh="generated_base_link_part006" pos="0 0 0" name="base_link_collision_6" contype="1" conaffinity="2" group="0" />
      <geom type="mesh" mesh="generated_base_link_part007" pos="0 0 0" name="base_link_collision_7" contype="1" conaffinity="2" group="0" />
      <geom type="mesh" mesh="generated_base_link_part008" pos="0 0 0" name="base_link_collision_8" contype="1" conaffinity="2" group="0" />
      <geom type="mesh" mesh="generated_base_link_part009" pos="0 0 0" name="base_link_collision_9" contype="1" conaffinity="2" group="0" />
      <geom type="mesh" mesh="generated_base_link_part010" pos="0 0 0" name="base_link_collision_10" contype="1" conaffinity="2" group="0" />
      <body name="base_force_pt_fl" pos="0.02719628 0.06807697 -0.03342401">
        <inertial pos="0 0 0" mass="1e-06" diaginertia="1e-09 1e-09 1e-09" />
      </body>
      <body name="base_force_pt_fr" pos="0.02719628 -0.04192303 -0.03342401">
        <inertial pos="0 0 0" mass="1e-06" diaginertia="1e-09 1e-09 1e-09" />
      </body>
      <body name="base_force_pt_bl" pos="-0.06280372 0.06807697 -0.03342401">
        <inertial pos="0 0 0" mass="1e-06" diaginertia="1e-09 1e-09 1e-09" />
      </body>
      <body name="base_force_pt_br" pos="-0.06280372 -0.04192303 -0.03342401">
        <inertial pos="0 0 0" mass="1e-06" diaginertia="1e-09 1e-09 1e-09" />
      </body>
      <body name="lf0_Link" pos="0 0.16885 0">
        <joint name="lf0_Joint" type="hinge" axis="0 -1 0" damping="0" />
        <inertial pos="-0.09972259 0.00404879 0.00010639" mass="0.3224201" diaginertia="0.000125495485 0.00170560175 0.00178264276" quat="0.717427384 -0.696027437 0.0284175469 -0.0060166269" />
        <geom type="mesh" mesh="visual_Left_thigh_link" pos="0 0 0" name="lf0_Link_collision_0" contype="1" conaffinity="2" group="0" />
        <body name="lf1_Link" pos="-0.18 0.0215 0">
          <joint name="lf1_Joint" type="hinge" axis="0 -1 0" range="-0.6 0.8" damping="0" />
          <inertial pos="3.675e-05 -0.00127153 -0.06944962" mass="0.3424614" diaginertia="0.000119841545 0.00215663525 0.00224419321" quat="0.488902785 0.480842398 0.525130159 -0.503987075" />
          <geom type="mesh" mesh="visual_Left_calf_link" pos="0 0 0" name="lf1_Link_collision_0" contype="1" conaffinity="2" group="0" />
          <site name="l_spring_p2" pos="0.022943 0 -0.032766" group="4" />
          <site name="l_fourbar_target" pos="0 -0.0215 0.065" group="4" />
          <body name="l_wheel_Link" pos="-0.0029362 0.02705 -0.19998">
            <joint name="l_wheel_Joint" type="hinge" axis="0 1 0" damping="0" />
            <inertial pos="-1.681e-05 -0.00660229 -0.00011513" mass="0.27783378" diaginertia="0.00026477 0.000265419546 0.000480800454" quat="-0.705228274 0.706252215 -0.0439029096 -0.043970727" />
            <geom type="mesh" mesh="visual_Left_wheel_link" pos="0 0 0" name="l_wheel_Link_visual_proxy" contype="0" conaffinity="0" group="1" />
            <geom type="cylinder" size="0.059 0.016" pos="0 -0.0066 0" euler="1.5708 0 0" name="l_wheel_Link_collision_0" contype="1" conaffinity="2" group="0" friction="0.8 0.005 0.0001" />
          </body>
        </body>
      </body>
      <body name="l_drive_bar" pos="0 0.16885 0" euler="0 -1.5561 0">
        <joint name="l_drive_bar_Joint" type="hinge" axis="0 -1 0" damping="0.1" armature="0.001" />
        <inertial pos="0 0 0" mass="0.01" diaginertia="1e-6 1e-6 1e-6" />
        <geom type="capsule" fromto="0 0 0 0.0605 0 0" size="0.004" rgba="1 0.5 0 0.8" contype="0" conaffinity="0" group="2" />
        <site name="l_spring_p1" pos="-0.039792 0 -0.004071" group="4" />
        <body name="l_coupler" pos="0.0605 0 0" euler="0 -1.5855 0">
          <joint name="l_coupler_Joint" type="hinge" axis="0 -1 0" damping="0.1" armature="0.001" />
          <inertial pos="0 0 0" mass="0.01" diaginertia="1e-6 1e-6 1e-6" />
          <geom type="capsule" fromto="0 0 0 0.170 0 0" size="0.003" rgba="0.6 0 0.8 0.8" contype="0" conaffinity="0" group="2" />
          <body name="l_coupler_end" pos="0.170 0 0">
            <inertial pos="0 0 0" mass="0.01" diaginertia="1e-6 1e-6 1e-6" />
            <site name="l_fourbar_end" pos="0 0 0" group="4" />
          </body>
        </body>
      </body>
      <body name="rf0_Link" pos="0 -0.16885 0">
        <joint name="rf0_Joint" type="hinge" axis="0 -1 0" damping="0" />
        <inertial pos="-0.09972259 -0.00404879 0.00010639" mass="0.32242009" diaginertia="0.000125495485 0.00170560175 0.00178264276" quat="-0.696027437 0.717427384 0.0060166269 -0.0284175469" />
        <geom type="mesh" mesh="visual_Right_thigh_link" pos="0 0 0" name="rf0_Link_collision_0" contype="1" conaffinity="2" group="0" />
        <body name="rf1_Link" pos="-0.18 -0.02 0">
          <joint name="rf1_Joint" type="hinge" axis="0 -1 0" range="-0.6 0.8" damping="0" />
          <inertial pos="0.00104447 0.00037451 -0.0702541" mass="0.31883211" diaginertia="0.000108575968 0.00214460919 0.00223028484" quat="0.492792214 0.475500192 0.519198251 -0.511359538" />
          <geom type="mesh" mesh="visual_Right_calf_link" pos="0 0 0" name="rf1_Link_collision_0" contype="1" conaffinity="2" group="0" />
          <site name="r_spring_p2" pos="0.022943 0 -0.032766" group="4" />
          <site name="r_fourbar_target" pos="0 0.02 0.065" group="4" />
          <body name="r_wheel_Link" pos="-0.0029362 -0.02705 -0.19998">
            <joint name="r_wheel_Joint" type="hinge" axis="0 -1 0" damping="0" />
            <inertial pos="-1.681e-05 0.0066023 -0.00011513" mass="0.2778338" diaginertia="0.00026477 0.000265419546 0.000480800454" quat="0.705228274 0.706252215 0.0439029096 -0.043970727" />
            <geom type="mesh" mesh="visual_Right_wheel_link" pos="0 0 0" name="r_wheel_Link_visual_proxy" contype="0" conaffinity="0" group="1" />
            <geom type="cylinder" size="0.059 0.016" pos="0 0.0066 0" euler="1.5708 0 0" name="r_wheel_Link_collision_0" contype="1" conaffinity="2" group="0" friction="0.8 0.005 0.0001" />
          </body>
        </body>
      </body>
      <body name="r_drive_bar" pos="0 -0.16885 0" euler="0 -1.5561 0">
        <joint name="r_drive_bar_Joint" type="hinge" axis="0 -1 0" damping="0.1" armature="0.001" />
        <inertial pos="0 0 0" mass="0.01" diaginertia="1e-6 1e-6 1e-6" />
        <geom type="capsule" fromto="0 0 0 0.0605 0 0" size="0.004" rgba="1 0.5 0 0.8" contype="0" conaffinity="0" group="2" />
        <site name="r_spring_p1" pos="-0.039792 0 -0.004071" group="4" />
        <body name="r_coupler" pos="0.0605 0 0" euler="0 -1.5855 0">
          <joint name="r_coupler_Joint" type="hinge" axis="0 -1 0" damping="0.1" armature="0.001" />
          <inertial pos="0 0 0" mass="0.01" diaginertia="1e-6 1e-6 1e-6" />
          <geom type="capsule" fromto="0 0 0 0.170 0 0" size="0.003" rgba="0.6 0 0.8 0.8" contype="0" conaffinity="0" group="2" />
          <body name="r_coupler_end" pos="0.170 0 0">
            <inertial pos="0 0 0" mass="0.01" diaginertia="1e-6 1e-6 1e-6" />
            <site name="r_fourbar_end" pos="0 0 0" group="4" />
          </body>
        </body>
      </body>
    </body>
  </worldbody>
  <equality>
    <connect site1="l_fourbar_end" site2="l_fourbar_target" solref="0.002 1" solimp="0.95 0.99 0.001 0.5 2" />
    <connect site1="r_fourbar_end" site2="r_fourbar_target" solref="0.002 1" solimp="0.95 0.99 0.001 0.5 2" />
  </equality>
  <tendon>
    <!-- 闭链主动杆限位使用当前装配分支下的后杆-前杆夹角，而不是后主动杆绝对角。 -->
    <fixed name="l_active_rod_angle" limited="true" range="0.12 1.36">
      <joint joint="l_drive_bar_Joint" coef="1" />
      <joint joint="lf0_Joint" coef="-1" />
    </fixed>
    <fixed name="r_active_rod_angle" limited="true" range="0.12 1.36">
      <joint joint="r_drive_bar_Joint" coef="1" />
      <joint joint="rf0_Joint" coef="-1" />
    </fixed>
    <spatial name="l_knee_spring" width="0.003" rgba="0.2 0.6 1 1">
      <site site="l_spring_p1" />
      <site site="l_spring_p2" />
    </spatial>
    <spatial name="r_knee_spring" width="0.003" rgba="0.2 0.6 1 1">
      <site site="r_spring_p1" />
      <site site="r_spring_p2" />
    </spatial>
  </tendon>
  <actuator>
    <!-- 气弹簧为恒定推力元件：正 bias force 会沿 tendon 长度增大的方向推开两端挂点。 -->
    <general name="l_knee_gas_spring" tendon="l_knee_spring" dyntype="none" gaintype="fixed" biastype="affine" gainprm="0" biasprm="300 0 0" />
    <general name="r_knee_gas_spring" tendon="r_knee_spring" dyntype="none" gaintype="fixed" biastype="affine" gainprm="0" biasprm="300 0 0" />
  </actuator>
  <!-- 执行器由 MJLab BuiltinPositionActuatorCfg / BuiltinVelocityActuatorCfg 程序化创建。 -->
</mujoco>
