<mujoco model="serialleg_closed_chain_v3_reexport">
  <compiler angle="radian" meshdir="../meshes" autolimits="true" strippath="false" />
  <option timestep="0.002" solver="Newton" cone="pyramidal" />
  <visual>
    <global offwidth="1280" offheight="720" />
  </visual>
  <default>
    <geom solref="0.004 1.5" solimp="0.85 0.99 0.005" />
    <joint damping="0" />
  </default>
  <asset>
    <texture name="grid" type="2d" builtin="checker" width="512" height="512" rgb1=".1 .2 .3" rgb2=".2 .3 .4" />
    <material name="grid" texture="grid" texrepeat="1 1" texuniform="true" reflectance=".2" />
    <mesh name="visual_lf_thigh" file="lf_thigh_link.STL" />
    <mesh name="visual_lf_calf_1" file="lf_calf_1_link.STL" />
    <mesh name="visual_lf_calf_2" file="lf_calf_2_link.STL" />
    <mesh name="visual_lf_calf_3" file="lf_calf_3_link.STL" />
    <mesh name="visual_lf_wheel" file="lf_wheel_link.STL" />
    <mesh name="visual_rf_thigh" file="rf_thigh_link.STL" />
    <mesh name="visual_rf_calf_1" file="rf_calf_1_link.STL" />
    <mesh name="visual_rf_calf_2" file="rf_calf_2_link.STL" />
    <mesh name="visual_rf_calf_3" file="rf_calf_3_link.STL" />
    <mesh name="visual_rf_wheel" file="rf_wheel_link.STL" />
    <mesh name="swcol_lf0_Link_00" file="sw_collision_v3/lf0_Link/lf0_Link_sw_env_00.stl" />
    <mesh name="swcol_lf0_Link_01" file="sw_collision_v3/lf0_Link/lf0_Link_sw_env_01.stl" />
    <mesh name="swcol_rf0_Link_00" file="sw_collision_v3/rf0_Link/rf0_Link_sw_env_00.stl" />
    <mesh name="swcol_rf0_Link_01" file="sw_collision_v3/rf0_Link/rf0_Link_sw_env_01.stl" />
    <mesh name="swcol_lf1_Link_00" file="sw_collision_v3/lf1_Link/lf1_Link_sw_env_00.stl" />
    <mesh name="swcol_rf1_Link_00" file="sw_collision_v3/rf1_Link/rf1_Link_sw_env_00.stl" />
    <mesh name="swcol_l_drive_bar_Link_00" file="sw_collision_v3/l_drive_bar_Link/l_drive_bar_Link_sw_env_00.stl" />
    <mesh name="swcol_r_drive_bar_Link_00" file="sw_collision_v3/r_drive_bar_Link/r_drive_bar_Link_sw_env_00.stl" />
    <mesh name="swcol_l_coupler_Link_00" file="sw_collision_v3/l_coupler_Link/l_coupler_Link_sw_env_00.stl" />
    <mesh name="swcol_r_coupler_Link_00" file="sw_collision_v3/r_coupler_Link/r_coupler_Link_sw_env_00.stl" />
  </asset>
  <worldbody>
    <geom name="floor" type="plane" size="0 0 .05" material="grid" friction="0.8 0.005 0.0001" contype="2" conaffinity="1" />
    <light name="spotlight" mode="targetbodycom" target="base_link" diffuse=".8 .8 .8" specular="0.3 0.3 0.3" pos="0 -6 4" cutoff="30" />
    <body name="base_link" pos="0 0 0.30">
      <freejoint />
      <inertial pos="-0.0092117 0.00016247 -0.036098" mass="8.7812" fullinertia="0.0096389 0.015059 0.014092 2.7645E-07 0.00018285 -3.642E-06" />
      <geom name="base_link_collision_bottom_plate" type="box" size="0.245 0.130 0.006" pos="0 0 -0.090" group="0" contype="1" conaffinity="2" />
      <geom name="base_link_collision_left_rail" type="box" size="0.1605 0.010 0.020" pos="0 0.100 -0.044" group="0" contype="1" conaffinity="2" />
      <geom name="base_link_collision_right_rail" type="box" size="0.1605 0.010 0.020" pos="0 -0.100 -0.044" group="0" contype="1" conaffinity="2" />
      <geom name="base_link_collision_front_armor" type="box" size="0.043 0.084 0.064" pos="0.232 0 0.006" group="0" contype="1" conaffinity="2" />
      <geom name="base_link_collision_rear_armor" type="box" size="0.043 0.084 0.064" pos="-0.232 0 0.006" group="0" contype="1" conaffinity="2" />
      <geom name="base_link_collision_center_deck" type="box" size="0.110 0.105 0.026" pos="0 0 0.035" group="0" contype="1" conaffinity="2" />
      <geom name="base_link_collision_top_plate" type="box" size="0.130 0.100 0.006" pos="0 0 0.082" group="0" contype="1" conaffinity="2" />
      <body name="lf0_Link" pos="0 0.16885 0">
        <joint name="lf0_Joint" type="hinge" axis="0 1 0" />
        <inertial pos="-0.099683 0.0040488 0.0028201" mass="0.32242" fullinertia="0.00011081 0.00099773 0.00091659 -3.9259E-06 -4.4366E-05 7.5295E-07" />
        <geom type="mesh" mesh="visual_lf_thigh" pos="0 0 0" name="lf0_Link_visual" contype="0" conaffinity="0" group="1" />
        <site name="lf_thigh_end" pos="-0.17993 0.009275 0.0049" size="0.008" rgba="1 0 0 1" />
        <geom name="lf0_Link_sw_env_col_00" type="mesh" group="0" contype="1" conaffinity="2" mesh="swcol_lf0_Link_00" />
        <geom name="lf0_Link_sw_env_col_01" type="mesh" group="0" contype="1" conaffinity="2" mesh="swcol_lf0_Link_01" />
      </body>
      <body name="l_drive_bar_Link" pos="0 0.16885 0">
        <joint name="l_drive_bar_Joint" type="hinge" axis="0 1 0" />
        <inertial pos="0.011855 0.01367 0.013396" mass="0.046353" fullinertia="2.2168E-05 4.0902E-05 1.9277E-05 4.3728E-08 1.1801E-05 4.9411E-08" />
        <geom type="mesh" mesh="visual_lf_calf_1" pos="0 0 0" name="l_drive_bar_Link_visual" contype="0" conaffinity="0" group="1" />
        <site name="l_spring_p1" pos="0.02004768 0.00923125 0.02265288" group="4" />
        <geom name="l_drive_bar_Link_sw_env_col_00" type="mesh" group="0" contype="0" conaffinity="0" mesh="swcol_l_drive_bar_Link_00" />
        <body name="l_coupler_Link" pos="0.04009536 0.00690000 0.04530576">
          <joint name="l_coupler_Joint" type="hinge" axis="0 1 0" />
          <inertial pos="-0.083003 0.0014652 0.013304" mass="0.023219" fullinertia="2.4906E-06 7.1074E-05 6.8931E-05 -3.2336E-07 1.2497E-06 7.0829E-08" />
          <geom type="mesh" mesh="visual_lf_calf_2" pos="0 0 0" name="l_coupler_Link_visual" contype="0" conaffinity="0" group="1" />
          <geom name="l_coupler_Link_sw_env_col_00" type="mesh" group="0" contype="0" conaffinity="0" mesh="swcol_l_coupler_Link_00" />
          <body name="lf1_Link" pos="-0.17 0.0146 0.0010863">
            <joint name="lf1_Joint" type="hinge" axis="0 -1 0" />
            <inertial pos="-0.0861837809740974 -0.0012822584000049 -0.100601144648751" mass="0.340762117120269" fullinertia="0.00105192847135328 0.00157182040496788 0.000535237570275352 6.48216803497654E-07 0.000643884551706139 1.04122511390687E-06" />
            <geom type="mesh" mesh="visual_lf_calf_3" pos="0 0 0" name="lf1_Link_visual" contype="0" conaffinity="0" group="1" />
            <site name="lf_calf_closure" pos="-0.05002536 -0.012225 -0.04149206" size="0.008" rgba="0 1 0 1" />
            <site name="l_spring_p2" pos="-0.02501268 -0.01226875 -0.02074603" group="4" />
            <geom name="lf1_Link_sw_env_col_00" type="mesh" group="0" contype="1" conaffinity="2" mesh="swcol_lf1_Link_00" />
            <body name="l_wheel_Link" pos="-0.15699 0.02705 -0.21049">
              <joint name="l_wheel_Joint" type="hinge" axis="0 1 0" />
              <inertial pos="-7.447E-05 -0.0066023 -8.9398E-05" mass="0.27783" fullinertia="0.00026016 0.00048008 0.00026044 1.3715E-07 -3.6596E-07 1.9898E-07" />
              <geom type="mesh" mesh="visual_lf_wheel" pos="0 0 0" name="l_wheel_Link_visual" contype="0" conaffinity="0" group="1" />
              <geom name="l_wheel_Link_collision_0" type="cylinder" size="0.059 0.016" pos="0 -0.0066 0" euler="1.5708 0 0" group="0" contype="1" conaffinity="2" friction="0.8 0.005 0.0001" />
            </body>
          </body>
        </body>
      </body>
      <body name="rf0_Link" pos="0 -0.16885 0">
        <joint name="rf0_Joint" type="hinge" axis="0 -1 0" />
        <inertial pos="-0.099683 -0.0040488 0.0028201" mass="0.32242" fullinertia="0.00011081 0.00099773 0.00091659 3.9259E-06 -4.4366E-05 -7.5295E-07" />
        <geom type="mesh" mesh="visual_rf_thigh" pos="0 0 0" name="rf0_Link_visual" contype="0" conaffinity="0" group="1" />
        <site name="rf_thigh_end" pos="-0.17993 -0.009275 0.0049" size="0.008" rgba="1 0 0 1" />
        <geom name="rf0_Link_sw_env_col_00" type="mesh" group="0" contype="1" conaffinity="2" mesh="swcol_rf0_Link_00" />
        <geom name="rf0_Link_sw_env_col_01" type="mesh" group="0" contype="1" conaffinity="2" mesh="swcol_rf0_Link_01" />
      </body>
      <body name="r_drive_bar_Link" pos="0 -0.16885 0">
        <joint name="r_drive_bar_Joint" type="hinge" axis="0 -1 0" />
        <inertial pos="0.011855 -0.01367 0.013396" mass="0.046353" fullinertia="2.2168E-05 4.0902E-05 1.9277E-05 -4.3728E-08 1.1801E-05 -4.9411E-08" />
        <geom type="mesh" mesh="visual_rf_calf_1" pos="0 0 0" name="r_drive_bar_Link_visual" contype="0" conaffinity="0" group="1" />
        <site name="r_spring_p1" pos="0.02004750 -0.00923125 0.02265300" group="4" />
        <geom name="r_drive_bar_Link_sw_env_col_00" type="mesh" group="0" contype="0" conaffinity="0" mesh="swcol_r_drive_bar_Link_00" />
        <body name="r_coupler_Link" pos="0.040095 -0.0069 0.045306">
          <joint name="r_coupler_Joint" type="hinge" axis="0 -1 0" />
          <inertial pos="-0.083003 -0.0014652 0.013304" mass="0.023219" fullinertia="2.4906E-06 7.1074E-05 6.8931E-05 3.2336E-07 1.2497E-06 -7.0829E-08" />
          <geom type="mesh" mesh="visual_rf_calf_2" pos="0 0 0" name="r_coupler_Link_visual" contype="0" conaffinity="0" group="1" />
          <geom name="r_coupler_Link_sw_env_col_00" type="mesh" group="0" contype="0" conaffinity="0" mesh="swcol_r_coupler_Link_00" />
          <body name="rf1_Link" pos="-0.17 -0.0131 0.0010863">
            <joint name="rf1_Joint" type="hinge" axis="0 1 0" />
            <inertial pos="-0.085837 0.00037451 -0.10195" mass="0.31883" fullinertia="0.0010505 0.0015707 0.0005342 -6.5468E-07 0.00064391 -9.5741E-07" />
            <geom type="mesh" mesh="visual_rf_calf_3" pos="0 0 0" name="rf1_Link_visual" contype="0" conaffinity="0" group="1" />
            <site name="rf_calf_closure" pos="-0.050025 0.010725 -0.0414923" size="0.008" rgba="0 1 0 1" />
            <site name="r_spring_p2" pos="-0.02501250 0.01076875 -0.02074615" group="4" />
            <geom name="rf1_Link_sw_env_col_00" type="mesh" group="0" contype="1" conaffinity="2" mesh="swcol_rf1_Link_00" />
            <body name="r_wheel_Link" pos="-0.15699 -0.02705 -0.21049">
              <joint name="r_wheel_Joint" type="hinge" axis="0 -1 0" />
              <inertial pos="-7.4469E-05 0.0066023 -8.94E-05" mass="0.27783" fullinertia="0.00026016 0.00048008 0.00026044 -1.3715E-07 -3.6596E-07 -1.9898E-07" />
              <geom type="mesh" mesh="visual_rf_wheel" pos="0 0 0" name="r_wheel_Link_visual" contype="0" conaffinity="0" group="1" />
              <geom name="r_wheel_Link_collision_0" type="cylinder" size="0.059 0.016" pos="0 0.0066 0" euler="1.5708 0 0" group="0" contype="1" conaffinity="2" friction="0.8 0.005 0.0001" />
            </body>
          </body>
        </body>
      </body>
    </body>
  </worldbody>
  <equality>
    <connect site1="lf_thigh_end" site2="lf_calf_closure" solref="0.002 1" solimp="0.95 0.99 0.001" />
    <connect site1="rf_thigh_end" site2="rf_calf_closure" solref="0.002 1" solimp="0.95 0.99 0.001" />
  </equality>
  <tendon>
    <fixed name="l_active_rod_angle" limited="true" range="0.12 1.36" solreflimit="0.001 1" solimplimit="0.99 0.999 0.00001 0.5 2">
      <joint joint="lf0_Joint" coef="1" />
      <joint joint="l_drive_bar_Joint" coef="-1" />
    </fixed>
    <fixed name="r_active_rod_angle" limited="true" range="0.12 1.36" solreflimit="0.001 1" solimplimit="0.99 0.999 0.00001 0.5 2">
      <joint joint="r_drive_bar_Joint" coef="1" />
      <joint joint="rf0_Joint" coef="-1" />
    </fixed>
    <spatial name="l_knee_spring" width="0.003" rgba="0.2 0.6 1 1">
      <site site="l_spring_p1" />
      <site site="l_spring_p2" />
    </spatial>
    <spatial name="r_knee_spring" width="0.003" rgba="0.2 0.6 1 1">
      <site site="r_spring_p1" />
      <site site="r_spring_p2" />
    </spatial>
  </tendon>
  <actuator>
    <general name="l_knee_gas_spring" tendon="l_knee_spring" dyntype="none" gaintype="fixed" biastype="affine" gainprm="0" biasprm="300 0 0" />
    <general name="r_knee_gas_spring" tendon="r_knee_spring" dyntype="none" gaintype="fixed" biastype="affine" gainprm="0" biasprm="300 0 0" />
  </actuator>
</mujoco>
