<?xml version='1.0' encoding='utf-8'?>
<mujoco model="serialleg_fourbar_surrogate_stair_visualbase_coacd_train">
  <compiler angle="radian" meshdir="../meshes" autolimits="true" strippath="false" />
  <option timestep="0.002" solver="Newton" cone="pyramidal" />
  <visual>
    <global offwidth="1280" offheight="720" />
  </visual>
  <default>
    <geom solref="0.004 1.5" solimp="0.85 0.99 0.005" />
    <joint damping="0" />
  </default>
  <asset>
    <texture name="grid" type="2d" builtin="checker" width="512" height="512" rgb1=".1 .2 .3" rgb2=".2 .3 .4" />
    <material name="grid" texture="grid" texrepeat="1 1" texuniform="true" reflectance=".2" />
    <mesh name="visual_swbase_base_link_00" file="sw_original_base/base_link_chunk_00.stl" />
    <mesh name="visual_swbase_base_link_01" file="sw_original_base/base_link_chunk_01.stl" />
    <mesh name="visual_swbase_base_link_02" file="sw_original_base/base_link_chunk_02.stl" />
    <mesh name="visual_swbase_base_link_03" file="sw_original_base/base_link_chunk_03.stl" />
    <mesh name="visual_swbase_base_link_04" file="sw_original_base/base_link_chunk_04.stl" />
    <mesh name="visual_swbase_base_link_05" file="sw_original_base/base_link_chunk_05.stl" />
    <mesh name="visual_swbase_base_link_06" file="sw_original_base/base_link_chunk_06.stl" />
    <mesh name="visual_swbase_base_link_07" file="sw_original_base/base_link_chunk_07.stl" />
    <mesh name="visual_swbase_base_link_08" file="sw_original_base/base_link_chunk_08.stl" />
    <mesh name="visual_swbase_base_link_09" file="sw_original_base/base_link_chunk_09.stl" />
    <mesh name="visual_swbase_base_link_10" file="sw_original_base/base_link_chunk_10.stl" />
    <mesh name="visual_swbase_base_link_11" file="sw_original_base/base_link_chunk_11.stl" />
    <mesh name="visual_swbase_base_link_12" file="sw_original_base/base_link_chunk_12.stl" />
    <mesh name="visual_lf_wheel" file="lf_wheel_link.STL" />
    <mesh name="visual_rf_wheel" file="rf_wheel_link.STL" />
    <mesh name="visual_lf_thigh" file="lf_thigh_link.STL" />
    <mesh name="visual_l_calf" file="lf_calf_3_link.STL" />
    <mesh name="visual_rf_thigh" file="rf_thigh_link.STL" />
    <mesh name="visual_r_calf" file="rf_calf_3_link.STL" />
    
    
    
    
    
    
    
    
    
    
    
    
    
    
    
    
    
    
    
    
    
    
    
    
    
    
    
    
    
    
    
    
    
    
    
    
    
    
    
    
    
    
    
    
    
    
    
    
    <mesh name="staircol_lf0_Link_00" file="sw_collision_v3/lf0_Link/lf0_Link_sw_env_00.stl" />
    <mesh name="staircol_lf0_Link_01" file="sw_collision_v3/lf0_Link/lf0_Link_sw_env_01.stl" />
    <mesh name="staircol_rf0_Link_00" file="sw_collision_v3/rf0_Link/rf0_Link_sw_env_00.stl" />
    <mesh name="staircol_rf0_Link_01" file="sw_collision_v3/rf0_Link/rf0_Link_sw_env_01.stl" />
    <mesh name="staircol_lf1_Link_00" file="sw_collision_v3/lf1_Link/lf1_Link_sw_env_00.stl" />
    <mesh name="staircol_rf1_Link_00" file="sw_collision_v3/rf1_Link/rf1_Link_sw_env_00.stl" />
  
    
    
    
    
    
    
    
    
    
    
  <mesh name="stair_base_visual_coacd_mesh_00" file="stair_base_visual_coacd_32/base_visual_coacd_part_00.stl" /><mesh name="stair_base_visual_coacd_mesh_01" file="stair_base_visual_coacd_32/base_visual_coacd_part_01.stl" /><mesh name="stair_base_visual_coacd_mesh_02" file="stair_base_visual_coacd_32/base_visual_coacd_part_02.stl" /><mesh name="stair_base_visual_coacd_mesh_03" file="stair_base_visual_coacd_32/base_visual_coacd_part_03.stl" /><mesh name="stair_base_visual_coacd_mesh_04" file="stair_base_visual_coacd_32/base_visual_coacd_part_04.stl" /><mesh name="stair_base_visual_coacd_mesh_05" file="stair_base_visual_coacd_32/base_visual_coacd_part_05.stl" /><mesh name="stair_base_visual_coacd_mesh_06" file="stair_base_visual_coacd_32/base_visual_coacd_part_06.stl" /><mesh name="stair_base_visual_coacd_mesh_07" file="stair_base_visual_coacd_32/base_visual_coacd_part_07.stl" /><mesh name="stair_base_visual_coacd_mesh_08" file="stair_base_visual_coacd_32/base_visual_coacd_part_08.stl" /><mesh name="stair_base_visual_coacd_mesh_09" file="stair_base_visual_coacd_32/base_visual_coacd_part_09.stl" /><mesh name="stair_base_visual_coacd_mesh_10" file="stair_base_visual_coacd_32/base_visual_coacd_part_10.stl" /><mesh name="stair_base_visual_coacd_mesh_11" file="stair_base_visual_coacd_32/base_visual_coacd_part_11.stl" /><mesh name="stair_base_visual_coacd_mesh_12" file="stair_base_visual_coacd_32/base_visual_coacd_part_12.stl" /><mesh name="stair_base_visual_coacd_mesh_13" file="stair_base_visual_coacd_32/base_visual_coacd_part_13.stl" /><mesh name="stair_base_visual_coacd_mesh_14" file="stair_base_visual_coacd_32/base_visual_coacd_part_14.stl" /><mesh name="stair_base_visual_coacd_mesh_15" file="stair_base_visual_coacd_32/base_visual_coacd_part_15.stl" /><mesh name="stair_base_visual_coacd_mesh_16" file="stair_base_visual_coacd_32/base_visual_coacd_part_16.stl" /><mesh name="stair_base_visual_coacd_mesh_17" file="stair_base_visual_coacd_32/base_visual_coacd_part_17.stl" /><mesh name="stair_base_visual_coacd_mesh_18" file="stair_base_visual_coacd_32/base_visual_coacd_part_18.stl" /><mesh name="stair_base_visual_coacd_mesh_19" file="stair_base_visual_coacd_32/base_visual_coacd_part_19.stl" /><mesh name="stair_base_visual_coacd_mesh_20" file="stair_base_visual_coacd_32/base_visual_coacd_part_20.stl" /><mesh name="stair_base_visual_coacd_mesh_21" file="stair_base_visual_coacd_32/base_visual_coacd_part_21.stl" /><mesh name="stair_base_visual_coacd_mesh_22" file="stair_base_visual_coacd_32/base_visual_coacd_part_22.stl" /><mesh name="stair_base_visual_coacd_mesh_23" file="stair_base_visual_coacd_32/base_visual_coacd_part_23.stl" /><mesh name="stair_base_visual_coacd_mesh_24" file="stair_base_visual_coacd_32/base_visual_coacd_part_24.stl" /><mesh name="stair_base_visual_coacd_mesh_25" file="stair_base_visual_coacd_32/base_visual_coacd_part_25.stl" /><mesh name="stair_base_visual_coacd_mesh_26" file="stair_base_visual_coacd_32/base_visual_coacd_part_26.stl" /><mesh name="stair_base_visual_coacd_mesh_27" file="stair_base_visual_coacd_32/base_visual_coacd_part_27.stl" /><mesh name="stair_base_visual_coacd_mesh_28" file="stair_base_visual_coacd_32/base_visual_coacd_part_28.stl" /><mesh name="stair_base_visual_coacd_mesh_29" file="stair_base_visual_coacd_32/base_visual_coacd_part_29.stl" /><mesh name="stair_base_visual_coacd_mesh_30" file="stair_base_visual_coacd_32/base_visual_coacd_part_30.stl" /><mesh name="stair_base_visual_coacd_mesh_31" file="stair_base_visual_coacd_32/base_visual_coacd_part_31.stl" /></asset>
  <worldbody>
    <geom name="floor" type="plane" size="0 0 .05" material="grid" friction="0.8 0.005 0.0001" contype="2" conaffinity="1" />
    <light name="spotlight" mode="targetbodycom" target="base_link" diffuse=".8 .8 .8" specular="0.3 0.3 0.3" pos="0 -6 4" cutoff="30" />
    <body name="base_link" pos="0 0 0.22">
      <site name="fourbar_surrogate_marker" pos="0 0 0" size="0.001" group="5" />
      <freejoint />
      <inertial pos="-0.01780372 0.01307697 -0.03342401" mass="10.74541262" fullinertia="0.14395729 0.21248062 0.30929562 -0.00229101 0.00807199 -0.00039793" />
      <geom name="base_link_collision_visual_coacd_00" type="mesh" mesh="stair_base_visual_coacd_mesh_00" group="0" contype="1" conaffinity="1" friction="0.8 0.005 0.0001" rgba="0.05 0.65 1.0 0.40" /><geom name="base_link_collision_visual_coacd_01" type="mesh" mesh="stair_base_visual_coacd_mesh_01" group="0" contype="1" conaffinity="1" friction="0.8 0.005 0.0001" rgba="0.05 0.65 1.0 0.40" /><geom name="base_link_collision_visual_coacd_02" type="mesh" mesh="stair_base_visual_coacd_mesh_02" group="0" contype="1" conaffinity="1" friction="0.8 0.005 0.0001" rgba="0.05 0.65 1.0 0.40" /><geom name="base_link_collision_visual_coacd_03" type="mesh" mesh="stair_base_visual_coacd_mesh_03" group="0" contype="1" conaffinity="1" friction="0.8 0.005 0.0001" rgba="0.05 0.65 1.0 0.40" /><geom name="base_link_collision_visual_coacd_04" type="mesh" mesh="stair_base_visual_coacd_mesh_04" group="0" contype="1" conaffinity="1" friction="0.8 0.005 0.0001" rgba="0.05 0.65 1.0 0.40" /><geom name="base_link_collision_visual_coacd_05" type="mesh" mesh="stair_base_visual_coacd_mesh_05" group="0" contype="1" conaffinity="1" friction="0.8 0.005 0.0001" rgba="0.05 0.65 1.0 0.40" /><geom name="base_link_collision_visual_coacd_06" type="mesh" mesh="stair_base_visual_coacd_mesh_06" group="0" contype="1" conaffinity="1" friction="0.8 0.005 0.0001" rgba="0.05 0.65 1.0 0.40" /><geom name="base_link_collision_visual_coacd_07" type="mesh" mesh="stair_base_visual_coacd_mesh_07" group="0" contype="1" conaffinity="1" friction="0.8 0.005 0.0001" rgba="0.05 0.65 1.0 0.40" /><geom name="base_link_collision_visual_coacd_08" type="mesh" mesh="stair_base_visual_coacd_mesh_08" group="0" contype="1" conaffinity="1" friction="0.8 0.005 0.0001" rgba="0.05 0.65 1.0 0.40" /><geom name="base_link_collision_visual_coacd_09" type="mesh" mesh="stair_base_visual_coacd_mesh_09" group="0" contype="1" conaffinity="1" friction="0.8 0.005 0.0001" rgba="0.05 0.65 1.0 0.40" /><geom name="base_link_collision_visual_coacd_10" type="mesh" mesh="stair_base_visual_coacd_mesh_10" group="0" contype="1" conaffinity="1" friction="0.8 0.005 0.0001" rgba="0.05 0.65 1.0 0.40" /><geom name="base_link_collision_visual_coacd_11" type="mesh" mesh="stair_base_visual_coacd_mesh_11" group="0" contype="1" conaffinity="1" friction="0.8 0.005 0.0001" rgba="0.05 0.65 1.0 0.40" /><geom name="base_link_collision_visual_coacd_12" type="mesh" mesh="stair_base_visual_coacd_mesh_12" group="0" contype="1" conaffinity="1" friction="0.8 0.005 0.0001" rgba="0.05 0.65 1.0 0.40" /><geom name="base_link_collision_visual_coacd_13" type="mesh" mesh="stair_base_visual_coacd_mesh_13" group="0" contype="1" conaffinity="1" friction="0.8 0.005 0.0001" rgba="0.05 0.65 1.0 0.40" /><geom name="base_link_collision_visual_coacd_14" type="mesh" mesh="stair_base_visual_coacd_mesh_14" group="0" contype="1" conaffinity="1" friction="0.8 0.005 0.0001" rgba="0.05 0.65 1.0 0.40" /><geom name="base_link_collision_visual_coacd_15" type="mesh" mesh="stair_base_visual_coacd_mesh_15" group="0" contype="1" conaffinity="1" friction="0.8 0.005 0.0001" rgba="0.05 0.65 1.0 0.40" /><geom name="base_link_collision_visual_coacd_16" type="mesh" mesh="stair_base_visual_coacd_mesh_16" group="0" contype="1" conaffinity="1" friction="0.8 0.005 0.0001" rgba="0.05 0.65 1.0 0.40" /><geom name="base_link_collision_visual_coacd_17" type="mesh" mesh="stair_base_visual_coacd_mesh_17" group="0" contype="1" conaffinity="1" friction="0.8 0.005 0.0001" rgba="0.05 0.65 1.0 0.40" /><geom name="base_link_collision_visual_coacd_18" type="mesh" mesh="stair_base_visual_coacd_mesh_18" group="0" contype="1" conaffinity="1" friction="0.8 0.005 0.0001" rgba="0.05 0.65 1.0 0.40" /><geom name="base_link_collision_visual_coacd_19" type="mesh" mesh="stair_base_visual_coacd_mesh_19" group="0" contype="1" conaffinity="1" friction="0.8 0.005 0.0001" rgba="0.05 0.65 1.0 0.40" /><geom name="base_link_collision_visual_coacd_20" type="mesh" mesh="stair_base_visual_coacd_mesh_20" group="0" contype="1" conaffinity="1" friction="0.8 0.005 0.0001" rgba="0.05 0.65 1.0 0.40" /><geom name="base_link_collision_visual_coacd_21" type="mesh" mesh="stair_base_visual_coacd_mesh_21" group="0" contype="1" conaffinity="1" friction="0.8 0.005 0.0001" rgba="0.05 0.65 1.0 0.40" /><geom name="base_link_collision_visual_coacd_22" type="mesh" mesh="stair_base_visual_coacd_mesh_22" group="0" contype="1" conaffinity="1" friction="0.8 0.005 0.0001" rgba="0.05 0.65 1.0 0.40" /><geom name="base_link_collision_visual_coacd_23" type="mesh" mesh="stair_base_visual_coacd_mesh_23" group="0" contype="1" conaffinity="1" friction="0.8 0.005 0.0001" rgba="0.05 0.65 1.0 0.40" /><geom name="base_link_collision_visual_coacd_24" type="mesh" mesh="stair_base_visual_coacd_mesh_24" group="0" contype="1" conaffinity="1" friction="0.8 0.005 0.0001" rgba="0.05 0.65 1.0 0.40" /><geom name="base_link_collision_visual_coacd_25" type="mesh" mesh="stair_base_visual_coacd_mesh_25" group="0" contype="1" conaffinity="1" friction="0.8 0.005 0.0001" rgba="0.05 0.65 1.0 0.40" /><geom name="base_link_collision_visual_coacd_26" type="mesh" mesh="stair_base_visual_coacd_mesh_26" group="0" contype="1" conaffinity="1" friction="0.8 0.005 0.0001" rgba="0.05 0.65 1.0 0.40" /><geom name="base_link_collision_visual_coacd_27" type="mesh" mesh="stair_base_visual_coacd_mesh_27" group="0" contype="1" conaffinity="1" friction="0.8 0.005 0.0001" rgba="0.05 0.65 1.0 0.40" /><geom name="base_link_collision_visual_coacd_28" type="mesh" mesh="stair_base_visual_coacd_mesh_28" group="0" contype="1" conaffinity="1" friction="0.8 0.005 0.0001" rgba="0.05 0.65 1.0 0.40" /><geom name="base_link_collision_visual_coacd_29" type="mesh" mesh="stair_base_visual_coacd_mesh_29" group="0" contype="1" conaffinity="1" friction="0.8 0.005 0.0001" rgba="0.05 0.65 1.0 0.40" /><geom name="base_link_collision_visual_coacd_30" type="mesh" mesh="stair_base_visual_coacd_mesh_30" group="0" contype="1" conaffinity="1" friction="0.8 0.005 0.0001" rgba="0.05 0.65 1.0 0.40" /><geom name="base_link_collision_visual_coacd_31" type="mesh" mesh="stair_base_visual_coacd_mesh_31" group="0" contype="1" conaffinity="1" friction="0.8 0.005 0.0001" rgba="0.05 0.65 1.0 0.40" /><geom name="base_link_sw_raw_visual_00" type="mesh" mesh="visual_swbase_base_link_00" contype="0" conaffinity="0" group="1" />
      <geom name="base_link_sw_raw_visual_01" type="mesh" mesh="visual_swbase_base_link_01" contype="0" conaffinity="0" group="1" />
      <geom name="base_link_sw_raw_visual_02" type="mesh" mesh="visual_swbase_base_link_02" contype="0" conaffinity="0" group="1" />
      <geom name="base_link_sw_raw_visual_03" type="mesh" mesh="visual_swbase_base_link_03" contype="0" conaffinity="0" group="1" />
      <geom name="base_link_sw_raw_visual_04" type="mesh" mesh="visual_swbase_base_link_04" contype="0" conaffinity="0" group="1" />
      <geom name="base_link_sw_raw_visual_05" type="mesh" mesh="visual_swbase_base_link_05" contype="0" conaffinity="0" group="1" />
      <geom name="base_link_sw_raw_visual_06" type="mesh" mesh="visual_swbase_base_link_06" contype="0" conaffinity="0" group="1" />
      <geom name="base_link_sw_raw_visual_07" type="mesh" mesh="visual_swbase_base_link_07" contype="0" conaffinity="0" group="1" />
      <geom name="base_link_sw_raw_visual_08" type="mesh" mesh="visual_swbase_base_link_08" contype="0" conaffinity="0" group="1" />
      <geom name="base_link_sw_raw_visual_09" type="mesh" mesh="visual_swbase_base_link_09" contype="0" conaffinity="0" group="1" />
      <geom name="base_link_sw_raw_visual_10" type="mesh" mesh="visual_swbase_base_link_10" contype="0" conaffinity="0" group="1" />
      <geom name="base_link_sw_raw_visual_11" type="mesh" mesh="visual_swbase_base_link_11" contype="0" conaffinity="0" group="1" />
      <geom name="base_link_sw_raw_visual_12" type="mesh" mesh="visual_swbase_base_link_12" contype="0" conaffinity="0" group="1" />
      
      
      
      
      
      
      
      
      
      
      
      
      
      
      
      
      
      
      
      
      
      
      
      
      
      
      
      
      
      
      
      
      
      
      
      
      
      
      
      
      
      
      
      
      
      
      
      
      
      
      
      
      
      
      
      
      
      
      
      
      
      
      
      
      
      
      
      
      
      
      
      
      
      
      
      <body name="lf0_Link" pos="0 0.16885 0">
        <joint name="lf0_Joint" type="hinge" axis="0 1 0" armature="0.01" limited="false" />
        <inertial pos="-0.09968276 0.00404879 0.00282013" mass="0.32242010" fullinertia="0.00013496 0.00177872 0.00170006 0.00007976 0.00009393 -0.00000238" />
        <geom name="lf0_Link_visual" type="mesh" mesh="visual_lf_thigh" contype="0" conaffinity="0" group="1" />
        <site name="lf_thigh_end" pos="-0.17993464 0.0215 0.00489576" size="0.008" rgba="1 0 0 1" />
        <site name="l_spring_p1" pos="0.00705 0.00497702 -0.04678497" group="4" />
        <geom name="lf0_Link_stair_col_00" mesh="staircol_lf0_Link_00" type="mesh" group="0" contype="1" conaffinity="2" />
        <geom name="lf0_Link_stair_col_01" mesh="staircol_lf0_Link_01" type="mesh" group="0" contype="1" conaffinity="2" />
        <body name="lf1_Link" pos="-0.12990117 0.0215 0.04639203">
          <joint name="lf1_Joint" type="hinge" pos="-0.05003347 0 -0.04149627" axis="0 1 0" damping="1" armature="0.02" limited="true" range="-1.389388135292 0" />
          <inertial pos="-0.04177153 -0.00094144 -0.06569666" mass="0.32184046" fullinertia="0.00126318 0.00185755 0.00061944 0.00000296 -0.00076497 0.00001136" />
          <geom name="lf1_Link_visual" type="mesh" mesh="visual_l_calf" contype="0" conaffinity="0" group="1" />
          <site name="lf_calf_closure" pos="-0.05003347 0 -0.04149627" size="0.008" rgba="0 1 0 1" />
          <site name="lf_coupler_closure" pos="0 0 0" size="0.008" rgba="0 0.7 1 1" />
          <site name="l_spring_p2" pos="-0.09034883 -0.01652298 -0.09317700" group="4" />
          <geom name="lf1_Link_stair_col_00" mesh="staircol_lf1_Link_00" type="mesh" group="0" contype="1" conaffinity="2" />
          <body name="l_wheel_Link" pos="-0.15699 0.02705 -0.21049">
            <joint name="l_wheel_Joint" type="hinge" axis="0 1 0" armature="0.005" />
            <inertial pos="-0.00007447 -0.00660229 -0.00008940" mass="0.27783378" fullinertia="0.00026503 0.00048080 0.00026516 -0.00000020 0.00000031 -0.00000025" />
            <geom type="mesh" mesh="visual_lf_wheel" pos="0 0 0" name="l_wheel_Link_visual" contype="0" conaffinity="0" group="1" />
            <geom name="l_wheel_Link_collision_0" type="cylinder" size="0.060 0.010" pos="0 -0.015925 0" euler="1.5708 0 0" group="0" contype="1" conaffinity="2" friction="0.8 0.005 0.0001" />
          </body>
        </body>
      </body>
      <body name="rf0_Link" pos="0 -0.16885 0">
        <joint name="rf0_Joint" type="hinge" axis="0 -1 0" armature="0.01" limited="false" />
        <inertial pos="-0.09968276 -0.00404879 0.00282013" mass="0.32242010" fullinertia="0.00013496 0.00177872 0.00170006 -0.00007976 0.00009393 0.00000238" />
        <geom name="rf0_Link_visual" type="mesh" mesh="visual_rf_thigh" contype="0" conaffinity="0" group="1" />
        <site name="rf_thigh_end" pos="-0.179935 -0.0200 0.004896" size="0.008" rgba="1 0 0 1" />
        <site name="r_spring_p1" pos="0.00705 -0.00497702 -0.04678497" group="4" />
        <geom name="rf0_Link_stair_col_00" mesh="staircol_rf0_Link_00" type="mesh" group="0" contype="1" conaffinity="2" />
        <geom name="rf0_Link_stair_col_01" mesh="staircol_rf0_Link_01" type="mesh" group="0" contype="1" conaffinity="2" />
        <body name="rf1_Link" pos="-0.12990153 -0.0200 0.04639227">
          <joint name="rf1_Joint" type="hinge" pos="-0.05003347 0 -0.04149627" axis="0 -1 0" damping="1" armature="0.02" limited="true" range="0 1.389388135292" />
          <inertial pos="-0.04177153 0.00094144 -0.06569666" mass="0.32184046" fullinertia="0.00126318 0.00185755 0.00061944 -0.00000296 -0.00076497 -0.00001136" />
          <geom name="rf1_Link_visual" type="mesh" mesh="visual_r_calf" contype="0" conaffinity="0" group="1" />
          <site name="rf_calf_closure" pos="-0.05003347 0 -0.04149627" size="0.008" rgba="0 1 0 1" />
          <site name="rf_coupler_closure" pos="0 0 0" size="0.008" rgba="0 0.7 1 1" />
          <site name="r_spring_p2" pos="-0.09034883 0.01502298 -0.09317700" group="4" />
          <geom name="rf1_Link_stair_col_00" mesh="staircol_rf1_Link_00" type="mesh" group="0" contype="1" conaffinity="2" />
          <body name="r_wheel_Link" pos="-0.15699 -0.02705 -0.21049">
            <joint name="r_wheel_Joint" type="hinge" axis="0 -1 0" armature="0.005" />
            <inertial pos="-0.00007447 0.00660229 -0.00008940" mass="0.27783378" fullinertia="0.00026503 0.00048080 0.00026516 0.00000020 0.00000031 0.00000025" />
            <geom type="mesh" mesh="visual_rf_wheel" pos="0 0 0" name="r_wheel_Link_visual" contype="0" conaffinity="0" group="1" />
            <geom name="r_wheel_Link_collision_0" type="cylinder" size="0.060 0.010" pos="0 0.015925 0" euler="1.5708 0 0" group="0" contype="1" conaffinity="2" friction="0.8 0.005 0.0001" />
          </body>
        </body>
      </body>
    </body>
  </worldbody>
  <tendon>
    <spatial name="l_knee_spring" width="0.003" rgba="0.2 0.6 1 1">
      <site site="l_spring_p1" />
      <site site="l_spring_p2" />
    </spatial>
    <spatial name="r_knee_spring" width="0.003" rgba="0.2 0.6 1 1">
      <site site="r_spring_p1" />
      <site site="r_spring_p2" />
    </spatial>
  </tendon>
  <keyframe>
    <key name="standing" qpos="0 0 0.22 1 0 0 0 -0.275422946189 -1.242259649307 0 0.275422946189 1.242259649307 0" />
  </keyframe>
</mujoco>