<mujoco model="minidog_16dof_16kg">
  <compiler angle="radian" autolimits="true" />
  <size njmax="256" nconmax="128" />
  <option timestep="0.005" iterations="80" solver="Newton" cone="pyramidal" />

  <default>
    <joint damping="0.08" armature="0.01" />
    <geom condim="3" contype="1" conaffinity="1" friction="0.8 0.01 0.001" solref="0.005 1" solimp="0.9 0.99 0.001" />
  </default>

  <asset>
    <material name="body_mat" rgba="0.25 0.30 0.36 1" />
    <material name="hip_mat" rgba="0.42 0.46 0.50 1" />
    <material name="leg_mat" rgba="0.70 0.72 0.74 1" />
    <material name="wheel_mat" rgba="0.03 0.03 0.035 1" />
    <material name="floor_mat" rgba="0.18 0.22 0.24 1" />
  </asset>

  <worldbody>
    <light name="key_light" directional="true" pos="-1 1 3" dir="0 0 -1" />
    <geom name="floor" type="plane" size="20 20 0.05" material="floor_mat" />

    <body name="base_link" pos="0 0 0.48">
      <freejoint name="floating_base" />
      <inertial pos="0 0 0" mass="7.360048" diaginertia="0.021219 0.186264 0.192647" />
      <geom name="base_collision" type="box" size="0.27 0.075 0.055" material="body_mat" />
      <site name="base_site" pos="0 0 0" size="0.005" rgba="1 0 0 1" />

      <body name="fl_abad_link" pos="0.25128 0.05500 0">
        <joint name="fl_abad_joint" type="hinge" axis="-1 0 0" range="-0.60 0.60" actuatorfrcrange="-50 50" />
        <inertial pos="0 0.02750 0" mass="0.120473" diaginertia="0.000050 0.000050 0.000050" />
        <geom name="fl_abad_collision" type="capsule" fromto="0 0 0 0 0.05500 0" size="0.024" material="hip_mat" />
        <body name="fl_hip_link" pos="0 0.05500 0">
          <inertial pos="0 0 0" mass="0.300000" diaginertia="0.000260 0.000260 0.000260" />
          <geom name="fl_hip_collision" type="box" size="0.045 0.032 0.036" material="hip_mat" />
          <body name="fl_thigh_link">
            <joint name="fl_hip_joint" type="hinge" axis="0 -1 0" range="-2.30 2.60" actuatorfrcrange="-50 50" />
            <inertial pos="0 0.02250 -0.10000" mass="0.913236" diaginertia="0.003350 0.003250 0.000340" />
            <geom name="fl_thigh_collision" type="capsule" fromto="0 0 0 0 0.04500 -0.20000" size="0.021" material="leg_mat" />
            <body name="fl_shank_link" pos="0 0.04500 -0.20000">
              <joint name="fl_knee_joint" type="hinge" axis="0 -1 0" range="-2.80 2.80" actuatorfrcrange="-50 50" />
              <inertial pos="0 0.01300 -0.10000" mass="0.530617" diaginertia="0.001850 0.001800 0.000200" />
              <geom name="fl_shank_collision" type="capsule" fromto="0 0 0 0 0.02600 -0.20000" size="0.018" material="leg_mat" />
              <body name="fl_wheel_link" pos="0 0.02600 -0.20000">
                <joint name="fl_wheel_joint" type="hinge" axis="0 -1 0" damping="0.02" armature="0.002" actuatorfrcrange="-12 12" />
                <inertial pos="0 0 0" mass="0.295662" diaginertia="0.000791 0.001533 0.000791" />
                <geom name="fl_wheel_collision" type="cylinder" size="0.072 0.022" euler="1.57079632679 0 0" material="wheel_mat" friction="1.0 0.01 0.001" />
              </body>
            </body>
          </body>
        </body>
      </body>

      <body name="fr_abad_link" pos="0.25128 -0.05500 0">
        <joint name="fr_abad_joint" type="hinge" axis="-1 0 0" range="-0.60 0.60" actuatorfrcrange="-50 50" />
        <inertial pos="0 -0.02750 0" mass="0.120473" diaginertia="0.000050 0.000050 0.000050" />
        <geom name="fr_abad_collision" type="capsule" fromto="0 0 0 0 -0.05500 0" size="0.024" material="hip_mat" />
        <body name="fr_hip_link" pos="0 -0.05500 0">
          <inertial pos="0 0 0" mass="0.300000" diaginertia="0.000260 0.000260 0.000260" />
          <geom name="fr_hip_collision" type="box" size="0.045 0.032 0.036" material="hip_mat" />
          <body name="fr_thigh_link">
            <joint name="fr_hip_joint" type="hinge" axis="0 -1 0" range="-2.30 2.60" actuatorfrcrange="-50 50" />
            <inertial pos="0 -0.02250 -0.10000" mass="0.913236" diaginertia="0.003350 0.003250 0.000340" />
            <geom name="fr_thigh_collision" type="capsule" fromto="0 0 0 0 -0.04500 -0.20000" size="0.021" material="leg_mat" />
            <body name="fr_shank_link" pos="0 -0.04500 -0.20000">
              <joint name="fr_knee_joint" type="hinge" axis="0 -1 0" range="-2.80 2.80" actuatorfrcrange="-50 50" />
              <inertial pos="0 -0.01300 -0.10000" mass="0.530617" diaginertia="0.001850 0.001800 0.000200" />
              <geom name="fr_shank_collision" type="capsule" fromto="0 0 0 0 -0.02600 -0.20000" size="0.018" material="leg_mat" />
              <body name="fr_wheel_link" pos="0 -0.02600 -0.20000">
                <joint name="fr_wheel_joint" type="hinge" axis="0 -1 0" damping="0.02" armature="0.002" actuatorfrcrange="-12 12" />
                <inertial pos="0 0 0" mass="0.295662" diaginertia="0.000791 0.001533 0.000791" />
                <geom name="fr_wheel_collision" type="cylinder" size="0.072 0.022" euler="1.57079632679 0 0" material="wheel_mat" friction="1.0 0.01 0.001" />
              </body>
            </body>
          </body>
        </body>
      </body>

      <body name="hl_abad_link" pos="-0.25128 0.05500 0">
        <joint name="hl_abad_joint" type="hinge" axis="-1 0 0" range="-0.60 0.60" actuatorfrcrange="-50 50" />
        <inertial pos="0 0.02750 0" mass="0.120473" diaginertia="0.000050 0.000050 0.000050" />
        <geom name="hl_abad_collision" type="capsule" fromto="0 0 0 0 0.05500 0" size="0.024" material="hip_mat" />
        <body name="hl_hip_link" pos="0 0.05500 0">
          <inertial pos="0 0 0" mass="0.300000" diaginertia="0.000260 0.000260 0.000260" />
          <geom name="hl_hip_collision" type="box" size="0.045 0.032 0.036" material="hip_mat" />
          <body name="hl_thigh_link">
            <joint name="hl_hip_joint" type="hinge" axis="0 -1 0" range="-2.60 2.30" actuatorfrcrange="-50 50" />
            <inertial pos="0 0.02250 -0.10000" mass="0.913236" diaginertia="0.003350 0.003250 0.000340" />
            <geom name="hl_thigh_collision" type="capsule" fromto="0 0 0 0 0.04500 -0.20000" size="0.021" material="leg_mat" />
            <body name="hl_shank_link" pos="0 0.04500 -0.20000">
              <joint name="hl_knee_joint" type="hinge" axis="0 -1 0" range="-2.80 2.80" actuatorfrcrange="-50 50" />
              <inertial pos="0 0.01300 -0.10000" mass="0.530617" diaginertia="0.001850 0.001800 0.000200" />
              <geom name="hl_shank_collision" type="capsule" fromto="0 0 0 0 0.02600 -0.20000" size="0.018" material="leg_mat" />
              <body name="hl_wheel_link" pos="0 0.02600 -0.20000">
                <joint name="hl_wheel_joint" type="hinge" axis="0 -1 0" damping="0.02" armature="0.002" actuatorfrcrange="-12 12" />
                <inertial pos="0 0 0" mass="0.295662" diaginertia="0.000791 0.001533 0.000791" />
                <geom name="hl_wheel_collision" type="cylinder" size="0.072 0.022" euler="1.57079632679 0 0" material="wheel_mat" friction="1.0 0.01 0.001" />
              </body>
            </body>
          </body>
        </body>
      </body>

      <body name="hr_abad_link" pos="-0.25128 -0.05500 0">
        <joint name="hr_abad_joint" type="hinge" axis="-1 0 0" range="-0.60 0.60" actuatorfrcrange="-50 50" />
        <inertial pos="0 -0.02750 0" mass="0.120473" diaginertia="0.000050 0.000050 0.000050" />
        <geom name="hr_abad_collision" type="capsule" fromto="0 0 0 0 -0.05500 0" size="0.024" material="hip_mat" />
        <body name="hr_hip_link" pos="0 -0.05500 0">
          <inertial pos="0 0 0" mass="0.300000" diaginertia="0.000260 0.000260 0.000260" />
          <geom name="hr_hip_collision" type="box" size="0.045 0.032 0.036" material="hip_mat" />
          <body name="hr_thigh_link">
            <joint name="hr_hip_joint" type="hinge" axis="0 -1 0" range="-2.60 2.30" actuatorfrcrange="-50 50" />
            <inertial pos="0 -0.02250 -0.10000" mass="0.913236" diaginertia="0.003350 0.003250 0.000340" />
            <geom name="hr_thigh_collision" type="capsule" fromto="0 0 0 0 -0.04500 -0.20000" size="0.021" material="leg_mat" />
            <body name="hr_shank_link" pos="0 -0.04500 -0.20000">
              <joint name="hr_knee_joint" type="hinge" axis="0 -1 0" range="-2.80 2.80" actuatorfrcrange="-50 50" />
              <inertial pos="0 -0.01300 -0.10000" mass="0.530617" diaginertia="0.001850 0.001800 0.000200" />
              <geom name="hr_shank_collision" type="capsule" fromto="0 0 0 0 -0.02600 -0.20000" size="0.018" material="leg_mat" />
              <body name="hr_wheel_link" pos="0 -0.02600 -0.20000">
                <joint name="hr_wheel_joint" type="hinge" axis="0 -1 0" damping="0.02" armature="0.002" actuatorfrcrange="-12 12" />
                <inertial pos="0 0 0" mass="0.295662" diaginertia="0.000791 0.001533 0.000791" />
                <geom name="hr_wheel_collision" type="cylinder" size="0.072 0.022" euler="1.57079632679 0 0" material="wheel_mat" friction="1.0 0.01 0.001" />
              </body>
            </body>
          </body>
        </body>
      </body>
    </body>
  </worldbody>

  <actuator>
    <motor name="fl_abad_motor" joint="fl_abad_joint" ctrllimited="true" ctrlrange="-50 50" gear="1" />
    <motor name="fl_hip_motor" joint="fl_hip_joint" ctrllimited="true" ctrlrange="-50 50" gear="1" />
    <motor name="fl_knee_motor" joint="fl_knee_joint" ctrllimited="true" ctrlrange="-50 50" gear="1" />
    <motor name="fl_wheel_motor" joint="fl_wheel_joint" ctrllimited="true" ctrlrange="-12 12" gear="1" />
    <motor name="fr_abad_motor" joint="fr_abad_joint" ctrllimited="true" ctrlrange="-50 50" gear="1" />
    <motor name="fr_hip_motor" joint="fr_hip_joint" ctrllimited="true" ctrlrange="-50 50" gear="1" />
    <motor name="fr_knee_motor" joint="fr_knee_joint" ctrllimited="true" ctrlrange="-50 50" gear="1" />
    <motor name="fr_wheel_motor" joint="fr_wheel_joint" ctrllimited="true" ctrlrange="-12 12" gear="1" />
    <motor name="hl_abad_motor" joint="hl_abad_joint" ctrllimited="true" ctrlrange="-50 50" gear="1" />
    <motor name="hl_hip_motor" joint="hl_hip_joint" ctrllimited="true" ctrlrange="-50 50" gear="1" />
    <motor name="hl_knee_motor" joint="hl_knee_joint" ctrllimited="true" ctrlrange="-50 50" gear="1" />
    <motor name="hl_wheel_motor" joint="hl_wheel_joint" ctrllimited="true" ctrlrange="-12 12" gear="1" />
    <motor name="hr_abad_motor" joint="hr_abad_joint" ctrllimited="true" ctrlrange="-50 50" gear="1" />
    <motor name="hr_hip_motor" joint="hr_hip_joint" ctrllimited="true" ctrlrange="-50 50" gear="1" />
    <motor name="hr_knee_motor" joint="hr_knee_joint" ctrllimited="true" ctrlrange="-50 50" gear="1" />
    <motor name="hr_wheel_motor" joint="hr_wheel_joint" ctrllimited="true" ctrlrange="-12 12" gear="1" />
  </actuator>

  <contact>
    <exclude body1="base_link" body2="fl_abad_link" />
    <exclude body1="fl_abad_link" body2="fl_hip_link" />
    <exclude body1="fl_hip_link" body2="fl_thigh_link" />
    <exclude body1="fl_thigh_link" body2="fl_shank_link" />
    <exclude body1="fl_shank_link" body2="fl_wheel_link" />
    <exclude body1="base_link" body2="fr_abad_link" />
    <exclude body1="fr_abad_link" body2="fr_hip_link" />
    <exclude body1="fr_hip_link" body2="fr_thigh_link" />
    <exclude body1="fr_thigh_link" body2="fr_shank_link" />
    <exclude body1="fr_shank_link" body2="fr_wheel_link" />
    <exclude body1="base_link" body2="hl_abad_link" />
    <exclude body1="hl_abad_link" body2="hl_hip_link" />
    <exclude body1="hl_hip_link" body2="hl_thigh_link" />
    <exclude body1="hl_thigh_link" body2="hl_shank_link" />
    <exclude body1="hl_shank_link" body2="hl_wheel_link" />
    <exclude body1="base_link" body2="hr_abad_link" />
    <exclude body1="hr_abad_link" body2="hr_hip_link" />
    <exclude body1="hr_hip_link" body2="hr_thigh_link" />
    <exclude body1="hr_thigh_link" body2="hr_shank_link" />
    <exclude body1="hr_shank_link" body2="hr_wheel_link" />
  </contact>
</mujoco>
